# 异常

### Java异常可分为以下两种

#### 1、Error

Error是Java虚拟机无法解决的问题。

**比如：**

1、递归时没有递归返回条件，导致方法栈爆满。

2、while循环没有退出循环体的条件。

#### 2、Exception

Exception是我们通常所说的异常。

**比如：**

空指针异常

数学运算异常

数组角标越界

类型异常等

## Exception

Exception和Error的父类是Throwavle.

Exception分为**编译时异常**和**运行时异常**

如下图，红色部分是编译时异常，右边蓝色部分是运行时异常。

**编译时异常就是在编写代码的时候，编译器捕获到的异常。如使用的变量没有定义，非void方法方法体没有return等。**

**运行时异常就是在运算时编译器才获取到的异常。**

![image-20220411205616639](C:\Users\鹤\AppData\Roaming\Typora\typora-user-images\image-20220411205616639.png)

### 异常处理

异常处理有两种方式

一种是try-catch-finally结构的异常处理。

一种是trows结构的异常处理

#### try-catch-finally

格式：

```java
try {
	//可能会出现异常的代码段
} catch (异常类型1 变量名1) {
    //处理异常的方式1
} catch (异常类型2 变量名2) {
    //处理异常的方式2
finally {
    //一定会执行的代码
}
```

**实例：**

​		1、**try将可能出现异常的代码块包装起来，当出现异常时，就会生成对应的异常对象，然后匹配相应的catch，寻找处理方法**。如果没有找到相应的catch，异常就被不会被处理，由编译器抛出异常，然后停止运行。如果找到了相应的catch，就将异常处理，然后正常运行。

​		2、异常被处理后就会跳出try-catch结果。

​		3、**如果catch中的异常类型中存在父子类关系，则父类应该放在子类后面。**

```java
public static void main(String[] args) {
    try {
        int i = 10/0;
        int a = 1;
        System.out.println(a);
    } catch (ArithmeticException e) {
        System.out.println("捕获到数学异常");
    } catch (NullPointerException e){
        System.out.println("捕获到空指针异常");
    }
    System.out.println("之后......");
}
```

结果：

![image-20220411214358623](C:\Users\鹤\AppData\Roaming\Typora\typora-user-images\image-20220411214358623.png)

被try包围的代码块的定义变量是局部变量，出了try范围就不能再使用了。

所以我们应该养成在try外定义变量，在try在使用变量的习惯。

例如：

把变量a放在try外面定义，后面就可以再次使用变量a。

```java
    public static void main(String[] args) {
        int i =0;
        int a =0;
        try {
            i = 10/0;
            a = 1;
            System.out.println(a);
        } catch (ArithmeticException e) {
            System.out.println("捕获到数学异常");
        } catch (NullPointerException e){
            System.out.println("捕获到空指针异常");
        }
        System.out.println("之后......");
        System.out.println(a);
    }
}
```

#### finally的使用

finally中的代码是一定会执行的，当catch中的代码出现异常，或者try代码块有return时，也会先执行finally里面的代码。

实例：

```java
public class test5 {
    public int test(){
        try {
            int i=10/0;
            return 1;
        } catch (ArithmeticException e) {
            e.printStackTrace();
            return 2;
        } finally {
            System.out.println("一定会执行的代码");
            return 3;
        }
    }

    public static void main(String[] args) {
        System.out.println(new test5().test());
    }
}
```

结果：

![image-20220412214114613](C:\Users\鹤\AppData\Roaming\Typora\typora-user-images\image-20220412214114613.png)

由于finally会在try代码块执行return语句之前先执行，所以finally中就直接执行return结束了方法。

**垃圾回收机制只回收JVM堆内存中的对象，不能回收数据库连接和、输入输出流、Socket连接等资源。**

**基于finally的特点，finall经常担任数据库连接和、输入输出流、Socket连接等资源的关闭工作。**

**即使在使用这些资源时出现了异常，也能正常的关闭这些资源。**

**try-catch-finally一般只处理编译时异常。**

## trows方式

throws的作用就是将异常抛给上层，即抛给调用该方法的方法。

上层方法接收到异常对象后，可以使用try-catch处理，也可用再次往上抛出异常。

#### 代码实例：

​		方法method2执行过程中如果出现找不到文件异常和其他IO异常时，会生成对应的异常对象，然后抛给调用method2的方法method1，method1又将异常抛给主方法，由主方法处理异常，然后method2停止运行。

​		**异常到了主方法最好不要再向上抛了，不然可能出现JVM出现异常终止。**

```java
public class Test6 {
    public static void main(String[] args) {
        Test6 test6 = new Test6();
        try {
            test6.method1();
        } catch (IOException e) {
            e.printStackTrace();
        }
    }
    void method1() throws IOException {
        method2();
    }
    void method2() throws FileNotFoundException, IOException {
        File file = new File("hello.txt");
        FileInputStream fis = new FileInputStream(file);
        int data = fis.read();
        while (data!=-1){
            System.out.println((char)data);
            data=fis.read();
        }
    }
}
```

**注意：子类重写的方法抛出异常类型应该要小于父类被重写方法的抛出异常类型**

**如果父类被重写的方法没有trows方式抛出异常，则子类重写这个方法也不能使用trows抛出异常。**

### throw

throw是一个生成异常对象的一个关键字。

**格式：throw new 异常类型(自定义异常信息)**

**throw与throws不同，throws是一个处理异常的过程，而throw只是生成一个异常对象。**

就像程序发现异常时会停止运行，在控制台打印异常信息，throw也一样，只不过，throw打印的异常信息是自己定义的。

**下面模仿登录时用户id输入不合法是，出现异常，停止运行。**

```java
public class Register {
    private int id;
    public static void main(String[] args) {
        Register register = new Register();
        register.register(0);
    }
    void register(int id){
        if(id>0){
            this.id=id;
        }else {
            throw new RuntimeException("用户id错误，停止运行");
        }
    }
}
```

**运行结果：**

![image-20220414202724657](C:\Users\鹤\AppData\Roaming\Typora\typora-user-images\image-20220414202724657.png)

**由throw生成的异常对象也可以通过throws抛出到上级方法，由上级方法处理。**

**例如：**

```java
public class Register {
    private int id;
    public static void main(String[] args) {
        Register register = new Register();
        try {
            register.register(0);
        } catch (Exception e) {
            System.out.println(e.getMessage());//获取自定义的异常信息
        }
    }
    void register(int id) throws Exception {//将throw生成的异常对象抛出
        if(id>0){
            this.id=id;
        }else {
            throw new Exception("用户id错误，停止运行");
        }
    }
}
```

**运行结果：**

![image-20220414203027143](C:\Users\鹤\AppData\Roaming\Typora\typora-user-images\image-20220414203027143.png)